Traceback (most recent call last):
  File "D:\SORTS\PyCharm\xrd-automated-tests\tests\xroad_client_registration_in_ss_221\client_registration_in_ss_2_2_1.py", line 134, in test_case
    check_expected_result_cs(self, ss_1_client, ss_2_client, ss_2_client_2)
  File "D:\SORTS\PyCharm\xrd-automated-tests\tests\xroad_client_registration_in_ss_221\client_registration_in_ss_2_2_1.py", line 488, in check_expected_result_cs
    '2.2.1-13.1: CHECKING IF CLIENT 2 EXISTS')
  File "D:\SORTS\PyCharm\xrd-automated-tests\main\assert_helper.py", line 27, in is_not_none
    self.case.assertIsNotNone(con1, msg)
  File "C:\Python27\lib\unittest\case.py", line 960, in assertIsNotNone
    self.fail(self._formatMessage(msg, standardMsg))
  File "C:\Python27\lib\unittest\case.py", line 410, in fail
    raise self.failureException(msg)
AssertionError: 2.2.1-13.1: CHECKING IF CLIENT 2 EXISTS FAILED
