Traceback (most recent call last):
  File "D:\SORTS\PyCharm\xrd-automated-tests\tests\xroad_client_registration_in_ss_221\client_registration_in_ss_2_2_1.py", line 102, in test_case
    add_client_to_ss_by_hand(self, ss_2_client)
  File "D:\SORTS\PyCharm\xrd-automated-tests\tests\xroad_client_registration_in_ss_221\client_registration_in_ss_2_2_1.py", line 318, in add_client_to_ss_by_hand
    '2.2.1-6: EXPECTED MESSAGE: {0}'.format('registration in progress')
  File "D:\SORTS\PyCharm\xrd-automated-tests\main\assert_helper.py", line 15, in is_equal
    self.case.assertEqual(con1, con2, msg)
  File "C:\Python27\lib\unittest\case.py", line 513, in assertEqual
    assertion_func(first, second, msg=msg)
  File "C:\Python27\lib\unittest\case.py", line 506, in _baseAssertEqual
    raise self.failureException(msg)
AssertionError: 2.2.1-6: TITLE NOT CORRECT: saved
