Traceback (most recent call last):
  File "D:\SORTS\PyCharm\xrd-automated-tests\tests\xroad_client_registration_in_ss_221\client_registration_in_ss_2_2_1.py", line 90, in test_case
    client_certification_2_1_3.test(client_code=ss_1_client['code'], client_class=ss_1_client['class'])(self)
  File "D:\SORTS\PyCharm\xrd-automated-tests\tests\xroad_ss_client_sertification_213\client_certification_2_1_3.py", line 35, in test_case
    self.config.get('ca.ssh_pass'))
  File "D:\SORTS\PyCharm\xrd-automated-tests\helpers\ssh_client.py", line 23, in __init__
    self.open(host, username, password)
  File "D:\SORTS\PyCharm\xrd-automated-tests\helpers\ssh_client.py", line 151, in open
    self.client.connect(host, username=username, password=password)
  File "C:\Python27\lib\site-packages\paramiko\client.py", line 380, in connect
    look_for_keys, gss_auth, gss_kex, gss_deleg_creds, gss_host)
  File "C:\Python27\lib\site-packages\paramiko\client.py", line 621, in _auth
    raise saved_exception
AuthenticationException: Authentication failed.
